Workbook
Name customers: Customers!$A$2:$F$12
Name Products: Products!$A$2:$H$11
Name rnlcountry: RandomNList!$N$3:$O$39
Name rnlsalesperson: RandomNList!$V$3:$X$13
Name rnlsegment: RandomNList!$S$2:$T$7
Name rnlunitsold: RandomNList!$O$3:$Q$39
Name Shippers: Shippers!$A$2:$H$6
Name Suppliers: Suppliers!$A$2:$E$4

Sheet AI-related
A1: Foreign Sentences
A2: Air yang tenang jangan disangka tiada buaya
A3: 半途而废, 不可思议
A4: 猿も木から落ちる
A5: 가재는 게 편
A6: ஏட்டுச் சுரக்காய் கூட்டுக்கு உதவாது
A7: Barking up the wrong tree
A8: ทูซอนเป็นชายหนุ่ม เขารักอเวนเจอร์
A9: My name is Daxun
A10: 图森是个年轻人，他喜欢复仇者
A11: ฉันชื่อ ดั๊กซัน
A12: Tucson seorang lelaki muda, dia suka Avenger
... A16: Alice is a profesional boxer, therefore she is qualified

Sheet Calendar
A1: Date | B1: Day | C1: Month | D1: Year | E1: WeekDayInNum | F1: WeekNumInYear
A2: 45292 | B2: =DAY(A2) -> 1 | C2: =MONTH(A2) -> 1 | D2: =YEAR(A2) -> 2024 | E2: =WEEKDAY(A2) -> 2 | F2: =_xlfn.ISOWEEKNUM(A2) -> 1
A3: 45293 | B3: =DAY(A3) -> 2 | C3: =MONTH(A3) -> 1 | D3: =YEAR(A3) -> 2024 | E3: =WEEKDAY(A3) -> 3 | F3: =_xlfn.ISOWEEKNUM(A3) -> 1
A4: 45294 | B4: =DAY(A4) -> 3 | C4: =MONTH(A4) -> 1 | D4: =YEAR(A4) -> 2024 | E4: =WEEKDAY(A4) -> 4 | F4: =_xlfn.ISOWEEKNUM(A4) -> 1
A5: 45295 | B5: =DAY(A5) -> 4 | C5: =MONTH(A5) -> 1 | D5: =YEAR(A5) -> 2024 | E5: =WEEKDAY(A5) -> 5 | F5: =_xlfn.ISOWEEKNUM(A5) -> 1
A6: 45296 | B6: =DAY(A6) -> 5 | C6: =MONTH(A6) -> 1 | D6: =YEAR(A6) -> 2024 | E6: =WEEKDAY(A6) -> 6 | F6: =_xlfn.ISOWEEKNUM(A6) -> 1
A7: 45297 | B7: =DAY(A7) -> 6 | C7: =MONTH(A7) -> 1 | D7: =YEAR(A7) -> 2024 | E7: =WEEKDAY(A7) -> 7 | F7: =_xlfn.ISOWEEKNUM(A7) -> 1
A8: 45298 | B8: =DAY(A8) -> 7 | C8: =MONTH(A8) -> 1 | D8: =YEAR(A8) -> 2024 | E8: =WEEKDAY(A8) -> 1 | F8: =_xlfn.ISOWEEKNUM(A8) -> 1
A9: 45299 | B9: =DAY(A9) -> 8 | C9: =MONTH(A9) -> 1 | D9: =YEAR(A9) -> 2024 | E9: =WEEKDAY(A9) -> 2 | F9: =_xlfn.ISOWEEKNUM(A9) -> 2
A10: 45300 | B10: =DAY(A10) -> 9 | C10: =MONTH(A10) -> 1 | D10: =YEAR(A10) -> 2024 | E10: =WEEKDAY(A10) -> 3 | F10: =_xlfn.ISOWEEKNUM(A10) -> 2
A11: 45301 | B11: =DAY(A11) -> 10 | C11: =MONTH(A11) -> 1 | D11: =YEAR(A11) -> 2024 | E11: =WEEKDAY(A11) -> 4 | F11: =_xlfn.ISOWEEKNUM(A11) -> 2
A12: 45302 | B12: =DAY(A12) -> 11 | C12: =MONTH(A12) -> 1 | D12: =YEAR(A12) -> 2024 | E12: =WEEKDAY(A12) -> 5 | F12: =_xlfn.ISOWEEKNUM(A12) -> 2
A13: 45303 | B13: =DAY(A13) -> 12 | C13: =MONTH(A13) -> 1 | D13: =YEAR(A13) -> 2024 | E13: =WEEKDAY(A13) -> 6 | F13: =_xlfn.ISOWEEKNUM(A13) -> 2
... A367: 45657 | B367: =DAY(A367) -> 31 | C367: =MONTH(A367) -> 12 | D367: =YEAR(A367) -> 2024 | E367: =WEEKDAY(A367) -> 3 | F367: =_xlfn.ISOWEEKNUM(A367) -> 1

Sheet Countries
A1: countrycode | B1: countryname | C1: isocode | D1: m49code | E1: continent | F1: region | G1: subregion
A2: 1 | B2: Afghanistan | C2: AFG | D2: 4 | E2: Asia | F2: Southern Asia
A3: 2 | B3: Åland Islands | C3: ALA | D3: 248 | E3: Europe | F3: Northern Europe
A4: 3 | B4: Albania | C4: ALB | D4: 8 | E4: Europe | F4: Southern Europe
A5: 4 | B5: Algeria | C5: DZA | D5: 12 | E5: Africa | F5: Northern Africa
A6: 5 | B6: American Samoa | C6: ASM | D6: 16 | E6: Oceania | F6: Polynesia
A7: 6 | B7: Andorra | C7: AND | D7: 20 | E7: Europe | F7: Southern Europe
A8: 7 | B8: Angola | C8: AGO | D8: 24 | E8: Africa | F8: Middle Africa | G8: Sub-Saharan Africa
A9: 8 | B9: Anguilla | C9: AIA | D9: 660 | E9: North America | F9: Caribbean | G9: Latin America and the Caribbean
A10: 9 | B10: Antarctica | C10: ATA | D10: 10 | E10: Antarctica | F10: Antarctica
A11: 10 | B11: Antigua and Barbuda | C11: ATG | D11: 28 | E11: North America | F11: Caribbean | G11: Latin America and the Caribbean
A12: 11 | B12: Argentina | C12: ARG | D12: 32 | E12: South America | F12: South America | G12: Latin America and the Caribbean
A13: 12 | B13: Armenia | C13: ARM | D13: 51 | E13: Asia | F13: Western Asia
A14: 13 | B14: Aruba | C14: ABW | D14: 533 | E14: North America | F14: Caribbean | G14: Latin America and the Caribbean
A15: 14 | B15: Australia | C15: AUS | D15: 36 | E15: Oceania | F15: Australia and New Zealand
A16: 15 | B16: Austria | C16: AUT | D16: 40 | E16: Europe | F16: Western Europe
A17: 16 | B17: Azerbaijan | C17: AZE | D17: 31 | E17: Asia | F17: Western Asia
A18: 17 | B18: Bahamas | C18: BHS | D18: 44 | E18: North America | F18: Caribbean | G18: Latin America and the Caribbean
A19: 18 | B19: Bahrain | C19: BHR | D19: 48 | E19: Asia | F19: Western Asia
A20: 19 | B20: Bangladesh | C20: BGD | D20: 50 | E20: Asia | F20: Southern Asia
A21: 20 | B21: Barbados | C21: BRB | D21: 52 | E21: North America | F21: Caribbean | G21: Latin America and the Caribbean
A22: 21 | B22: Belarus | C22: BLR | D22: 112 | E22: Europe | F22: Eastern Europe
A23: 22 | B23: Belgium | C23: BEL | D23: 56 | E23: Europe | F23: Western Europe
A24: 23 | B24: Belize | C24: BLZ | D24: 84 | E24: North America | F24: Central America | G24: Latin America and the Caribbean
A25: 24 | B25: Benin | C25: BEN | D25: 204 | E25: Africa | F25: Western Africa | G25: Sub-Saharan Africa
A26: 25 | B26: Bermuda | C26: BMU | D26: 60 | E26: North America | F26: Northern America
A27: 26 | B27: Bhutan | C27: BTN | D27: 64 | E27: Asia | F27: Southern Asia
A28: 27 | B28: Bolivia (Plurinational State of) | C28: BOL | D28: 68 | E28: South America | F28: South America | G28: Latin America and the Caribbean
A29: 28 | B29: Bonaire, Sint Eustatius and Saba | C29: BES | D29: 535 | E29: North America | F29: Caribbean | G29: Latin America and the Caribbean
A30: 29 | B30: Bosnia and Herzegovina | C30: BIH | D30: 70 | E30: Europe | F30: Southern Europe
A31: 30 | B31: Botswana | C31: BWA | D31: 72 | E31: Africa | F31: Southern Africa | G31: Sub-Saharan Africa
A32: 31 | B32: Bouvet Island | C32: BVT | D32: 74 | E32: South America | F32: South America | G32: Latin America and the Caribbean
A33: 32 | B33: Brazil | C33: BRA | D33: 76 | E33: South America | F33: South America | G33: Latin America and the Caribbean
A34: 33 | B34: British Indian Ocean Territory | C34: IOT | D34: 86 | E34: Africa | F34: Eastern Africa | G34: Sub-Saharan Africa
A35: 34 | B35: British Virgin Islands | C35: VGB | D35: 92 | E35: North America | F35: Caribbean | G35: Latin America and the Caribbean
A36: 35 | B36: Brunei Darussalam | C36: BRN | D36: 96 | E36: Asia | F36: South-eastern Asia
A37: 36 | B37: Bulgaria | C37: BGR | D37: 100 | E37: Europe | F37: Eastern Europe
A38: 37 | B38: Burkina Faso | C38: BFA | D38: 854 | E38: Africa | F38: Western Africa | G38: Sub-Saharan Africa
A39: 38 | B39: Burundi | C39: BDI | D39: 108 | E39: Africa | F39: Eastern Africa | G39: Sub-Saharan Africa
A40: 39 | B40: Cabo Verde | C40: CPV | D40: 132 | E40: Africa | F40: Western Africa | G40: Sub-Saharan Africa
...

Sheet Customers
A1: CustomerID | B1: Name | C1: Company | D1: Phone | E1: Manager | F1: CountryKey
A2: 1 | B2: Theresa Yulia | C2: Enterprise ABC | D2: 2467355553 | F2: 50
A3: 2 | B3: John Lee | C3: Json Pro Co | D3: 1363718361 | F3: 11
A4: 3 | B4: Lily Sayap | C4: Json Pro Co | D4: 5445855711 | E4: John Lee | F4: 11
A5: 4 | B5: Jon Celency | C5: XM ABC LTD | D5: 4558878512 | F5: 68
A6: 5 | B6: Mike Poi | C6: XM ABC LTD | D6: 1626258811 | E6: Jon Celency | F6: 123
A7: 6 | B7: Danny Koi | C7: MTT Asia | D7: 2223354558 | F7: 99
A8: 7 | B8: Mike Pence | C8: Grocer Jaya | D8: 3454588543 | F8: 99
A9: 8 | B9: Shashini Kaur | C9: Shima Apparel BHD | D9: 1325464887 | F9: 88
A10: 9 | B10: Kelvin Kelvin | C10: ABC Sdn Bhd | D10: 1231231212 | F10: 99
A11: 10 | B11: Khairul Amin | C11: Json Pro Co | D11: 2838333882 | E11: John Lee | F11: 44
A12: 11 | B12: Aruntha | C12: Json Pro Co | D12: 7636638228 | E12: John Lee | F12: 34

Sheet Employees
A1: EmployeeID | B1: Subsidiaries | C1: Name | D1: Phone | E1: Branch | F1: Manager | G1: Department | H1: Salary | I1: Hired Date | J1: Photo URL | K1: payrollid | L1: Email
A2: A0001 | B2: Quintegral | C2: Osawa | D2: 1796836765 | E2: SG | G2: Directors | H2: 5000 | I2: 36526 | J2: https://media.licdn.com/dms/image/C5103AQHWwMWwU3_xFw/profile-displayphoto-shrink_200_200/0/1573453831848?e=2147483647&v=beta&t=RsdxDeqVGdLFh50A6dayXBDVyxDBygawnZii0N5fypo | K2: 111 | L2: osawa@trainocate.com
A3: B0001 | B3: Trainocate | C3: Ruby Kaur | D3: 2357139323 | E3: KL | F3: Osawa | G3: Sales | H3: 4000 | I3: 36527 | J3: https://media.licdn.com/dms/image/C5603AQEp0Nlx8pMqvA/profile-displayphoto-shrink_200_200/0/1631970619329?e=2147483647&v=beta&t=XXbm42Ksr4m6iqds2r-VFeKf_fLoJUGQgxQjdNi2ejc | K3: 8888 | L3: ruby kaur@trainocate.com
A4: B0101 | B4: Trainocate | C4: Ming De Kuen | D4: 1245245672 | E4: PJ | F4: Brian Ng | G4: Operation | H4: 1001 | I4: 36557 | J4: https://encrypted-tbn0.gstatic.com/images?q=tbn:ANd9GcQxYHeAsBjrW2nlOOhNvMkJw8Ferup7PCx7vg&s | K4: 82482 | L4: mingdekuen@jasonwccyahoo375.onmicrosoft.com
A5: C0002 | B5: Quintegral | C5: Devi Sunes | D5: 3052465381 | E5: KL | F5: Ruby Kaur | G5: Sales | H5: 3003 | I5: 36557 | J5: https://i1.sndcdn.com/artworks-000065790486-rloedr-t500x500.jpg | K5: 5555 | L5: devisunes@jasonwccyahoo375.onmicrosoft.com
A6: C0003 | B6: Trainocate | C6: Jason Wong | D6: 1625535511 | E6: KL | F6: Brian Ng | G6: Operation | H6: 1002 | I6: 36984 | J6: https://i.ibb.co/Tx6Bq9Kq/selfportrait2.jpg | K6: 12347 | L6: jasonwong@jasonwccyahoo375.onmicrosoft.com
A7: C0005 | B7: Trainocate | C7: Llian Vecteezy | D7: 2325587855 | E7: PJ | F7: Jason Wong | G7: Trainers | H7: 2002 | I7: 36557 | J7: https://encrypted-tbn0.gstatic.com/images?q=tbn:ANd9GcR0Dguf61DgFkQ8wlvN58xZYpSRabRB5XAchQ&s | K7: 22254 | L7: llianvecteezy@jasonwccyahoo375.onmicrosoft.com
A8: C0011 | B8: Trainocate | C8: Brian Micolai | D8: 1028777351 | E8: KL | F8: Ruby Kaur | G8: Trainers | H8: 2003 | I8: 36984 | J8: https://upload.wikimedia.org/wikipedia/commons/thumb/1/18/Brian_McKnight_by_Gage_Skidmore_2.jpg/1200px-Brian_McKnight_by_Gage_Skidmore_2.jpg | K8: 76478 | L8: brian@jasonwccyahoo375.onmicrosoft.com
A9: C0020 | B9: Quintegral | C9: Abu Bakar | D9: 2067405812 | E9: PJ | F9: Pater Aria | G9: Sales | H9: 3002 | I9: 36984 | J9: https://www.kosmo.com.my/wp-content/uploads/2020/08/Abu1.jpeg | K9: 4444 | L9: abubakar@jasonwccyahoo375.onmicrosoft.com
A10: E0001 | B10: Quintegral | C10: Pater Aria | D10: 2115467679 | E10: SG | F10: Ruby Kaur | G10: Sales | H10: 3002 | I10: 37381 | J10: https://encrypted-tbn0.gstatic.com/images?q=tbn:ANd9GcQxURLS1gw7oJL0GrgROD-aI1igxgbnGnvxeg&s | K10: 1111 | L10: pateraria@jasonwccyahoo375.onmicrosoft.com
A11: E0012 | B11: Quintegral | C11: Jamal Ahmad | D11: 2748855584 | E11: SG | F11: Pater Aria | G11: Sales | H11: 3001 | I11: 37413 | J11: https://yt3.googleusercontent.com/ytc/AIdro_nv6vX-VnX5EE9T6MyXhu3u80r1zGRMJkKPijrx6vZEcQ=s900-c-k-c0x00ffffff-no-rj | K11: 2222 | L11: jamalahmad@jasonwccyahoo375.onmicrosoft.com
A12: E0013 | B12: Quintegral | C12: Sofia Kowalskki | D12: 1184824538 | E12: SG | F12: Ruby Kaur | G12: Sales | H12: 3002 | I12: 37383 | J12: https://64.media.tumblr.com/7ed3a9bfc51621f7f0e8cf1ee6dfba57/tumblr_mh7r7cddVu1r1cbjpo1_640.jpg | K12: 3333 | L12: sofiakowalskki@jasonwccyahoo375.onmicrosoft.com
A13: F0001 | B13: Trainocate | C13: Peter Pan | D13: 1231293923 | E13: PJ | F13: Brian Ng | G13: Operation | H13: 1500 | I13: 37383 | K13: 9999 | L13: peterpan@jasonwccyahoo375.onmicrosoft.com

Sheet jsonxml
A1: JSON | B1: XML
A2: [{"model":"Mazda RX4","mpg":21,"cyl":6,"disp":160,"hp":110,"drat":3.9,"wt":2.62,"qsec":16.46,"vs":0,"am":1,"gear":4,"carb":4}, {"model":"Mazda RX4 Wag","mpg":21,"cyl":6,"disp":160,"hp":110,"drat":3.9,"wt":2.875,"qsec":17.02,"vs":0,"am":1,"gear":4,"carb":4}, {"model":"Datsun 710","mpg":22.8,"cyl":4,"disp":108,"hp":93,"drat":3.85,"wt":2.32,"qsec":18.61,"vs":1,"am":1,"gear":4,"carb":1}, {"model":"Hornet 4 Drive","mpg":21.4,"cyl":6,"disp":258,"hp":110,"drat":3.08,"wt":3.215,"qsec":19.44,"vs":1,"am":0,"gear":3,"carb":1}, {"model":"Hornet Sportabout","mpg":18.7,"cyl":8,"disp":360,"hp":175,"drat":3.15,"wt":3.44,"qsec":17.02,"vs":0,"am":0,"gear":3,"carb":2}, {"model":"Valiant","mpg":18.1,"cyl":6,"disp":225,"hp":105,"drat":2.76,"wt":3.46,"qsec":20.22,"vs":1,"am":0,"gear":3,"carb":1}, {"model":"Duster 360","mpg":14.3,"cyl":8,"disp":360,"hp":245,"drat":3.21,"wt":3.57,"qsec":15.84,"vs":0,"am":0,"gear":3,"carb":4}, {"model":"Merc 240D","mpg":24.4,"cyl":4,"disp":146.7,"hp":62,"drat":3.69,"wt":3.19,"qsec":20,"vs":1,"am":0,"gear":4,"carb":2}, {"model":"Merc 230","mpg":22.8,"cyl":4,"disp":140.8,"hp":95,"drat":3.92,"wt":3.15,"qsec":22.9,"vs":1,"am":0,"gear":4,"carb":2}] | B2: <?xml version="1.0"?> <catalog> <book id="bk101"> <author>Gambardella, Matthew</author> <title>XML Developer's Guide</title> <genre>Computer</genre> <price>44.95</price> <publish_date>2000-10-01</publish_date> <description>An in-depth look at creating applications with XML.</description> </book> <book id="bk102"> <author>Ralls, Kim</author> <title>Midnight Rain</title> <genre>Fantasy</genre> <price>5.95</price> <publish_date>2000-12-16</publish_date> <description>A former architect battles corporate zombies, an evil sorceress, and her own childhood to become queen of the world.</description> </book> <book id="bk103"> <author>Corets, Eva</author> <title>Maeve Ascendant</title> <genre>Fantasy</genre> <price>5.95</price> <publish_date>2000-11-17</publish_date> <description>After the collapse of a nanotechnology society in England, the young survivors lay the foundation for a new society.</description> </book> <book id="bk104"> <author>Corets, Eva</author> <title>Oberon's Legacy</title> <genre>Fantasy</genre> <price>5.95</price> <publish_date>2001-03-10</publish_date> <description>In post-apocalypse England, the mysterious agent known only as Oberon helps to create a new life for the inhabitants of London. Sequel to Maeve Ascendant.</description> </book> <book id="bk105"> <author>Corets, Eva</author> <title>The Sundered Grail</title> <genre>Fantasy</genre> <price>5.95</price> <publish_date>2001-09-10</publish_date> <description>The two daughters of Maeve, half-sisters, battle one another for control of England. Sequel to Oberon's Legacy.</description> </book> <book id="bk106"> <author>Randall, Cynthia</author> <title>Lover Birds</title> <genre>Romance</genre> <price>4.95</price> <publish_date>2000-09-02</publish_date> <description>When Carla meets Paul at an ornithology conference, tempers fly as feathers get ruffled.</description> </book> <book id="bk107"> <author>Thurman, Paula</author> <title>Splish Splash</title> <genre>Romance</genre> <price>4.95</price> <publish_date>2000-11-02</publish_date> <description>A deep sea diver finds true love twenty thousand leagues beneath the sea.</description> </book> <book id="bk108"> <author>Knorr, Stefan</author> <title>Creepy Crawlies</title> <genre>Horror</genre> <price>4.95</price> <publish_date>2000-12-06</publish_date> <description>An anthology of horror stories about roaches, centipedes, scorpions and other insects.</description> </book> <book id="bk109"> <author>Kress, Peter</author> <title>Paradox Lost</title> <genre>Science Fiction</genre> <price>6.95</price> <publish_date>2000-11-02</publish_date> <description>After an inadvertant trip through a Heisenberg Uncertainty Device, James Salway discovers the problems of being quantum.</description> </book> <book id="bk110"> <author>O'Brien, Tim</author> <title>Microsoft .NET: The Programming Bible</title> <genre>Computer</genre> <price>36.95</price> <publish_date>2000-12-09</publish_date> <description>Microsoft's .NET initiative is explored in detail in this deep programmer's reference.</description> </book> <book id="bk111"> <author>O'Brien, Tim</author> <title>MSXML3: A Comprehensive Guide</title> <genre>Computer</genre> <price>36.95</price> <publish_date>2000-12-01</publish_date> <description>The Microsoft MSXML3 parser is covered in detail, with attention to XML DOM interfaces, XSLT processing, SAX and more.</description> </book> <book id="bk112"> <author>Galos, Mike</author> <title>Visual Studio 7: A Comprehensive Guide</title> <genre>Computer</genre> <price>49.95</price> <publish_date>2001-04-16</publish_date> <description>Microsoft Visual Studio 7 is explored in depth, looking at how Visual Basic, Visual C++, C#, and ASP+ are integrated into a comprehensive development environment.</description> </book> </catalog>
A3: [ { color: "red", value: "#f00" }, { color: "green", value: "#0f0" }, { color: "blue", value: "#00f" }, { color: "cyan", value: "#0ff" }, { color: "magenta", value: "#f0f" }, { color: "yellow", value: "#ff0" }, { color: "black", value: "#000" } ]

Sheet Orders
A1: orderid | B1: orderdate | C1: shipdate | D1: requireddate | E1: taxable | F1: CustID | G1: email
A2: 1 | B2: 45149 | C2: 45151 | D2: 45153 | E2: yes | F2: 6 | G2: ruby kaur@trainocate.com
A3: 2 | B3: 44420 | C3: 44422 | D3: 44425 | E3: no | F3: 4 | G3: mingdekuen@jasonwccyahoo375.onmicrosoft.com
A4: 3 | B4: 45170 | C4: 45172 | D4: 45173 | E4: no | F4: 5 | G4: devisunes@jasonwccyahoo375.onmicrosoft.com
A5: 4 | B5: 44369 | C5: 44371 | D5: 44372 | E5: no | F5: 7 | G5: jasonwong@jasonwccyahoo375.onmicrosoft.com
A6: 5 | B6: 44582 | C6: 44584 | D6: 44587 | E6: yes | F6: 6 | G6: llianvecteezy@jasonwccyahoo375.onmicrosoft.com
A7: 6 | B7: 45105 | C7: =+B7+3 -> 45108 | D7: =+C7+5 -> 45113 | E7: yes | F7: 5 | G7: brian@jasonwccyahoo375.onmicrosoft.com
A8: 7 | B8: 44229 | C8: 44231 | D8: 44234 | E8: yes | F8: 7 | G8: abubakar@jasonwccyahoo375.onmicrosoft.com
A9: 8 | B9: 44399 | C9: 44402 | D9: 44403 | E9: yes | F9: 6 | G9: pateraria@jasonwccyahoo375.onmicrosoft.com
A10: 9 | B10: 44213 | C10: 44214 | D10: 44217 | E10: no | F10: 8 | G10: jamalahmad@jasonwccyahoo375.onmicrosoft.com
A11: 10 | B11: 44389 | C11: 44391 | D11: 44392 | E11: no | F11: 7 | G11: sofiakowalskki@jasonwccyahoo375.onmicrosoft.com
A12: 11 | B12: 45120 | C12: 45122 | D12: 45124 | E12: no | F12: 5 | G12: peterpan@jasonwccyahoo375.onmicrosoft.com
A13: 12 | B13: 44228 | C13: 44230 | D13: 44231 | E13: yes | F13: 5 | G13: ruby kaur@trainocate.com
A14: 13 | B14: 45281 | C14: 45283 | D14: 45285 | E14: yes | F14: 5 | G14: mingdekuen@jasonwccyahoo375.onmicrosoft.com
A15: 14 | B15: 45119 | C15: 45122 | D15: 45123 | E15: no | F15: 3 | G15: devisunes@jasonwccyahoo375.onmicrosoft.com
A16: 15 | B16: 44590 | C16: 44592 | D16: 44593 | E16: no | F16: 6 | G16: jasonwong@jasonwccyahoo375.onmicrosoft.com
A17: 16 | B17: 44858 | C17: 44860 | D17: 44861 | E17: yes | F17: 7 | G17: llianvecteezy@jasonwccyahoo375.onmicrosoft.com
A18: 17 | B18: 44533 | C18: 44534 | D18: 44536 | E18: no | F18: 8 | G18: brian@jasonwccyahoo375.onmicrosoft.com
A19: 18 | B19: 44618 | C19: 44619 | D19: 44620 | E19: no | F19: 2 | G19: abubakar@jasonwccyahoo375.onmicrosoft.com
... A71: 70 | B71: 44777 | C71: 44778 | D71: 44781 | E71: yes | F71: 3 | G71: peterpan@jasonwccyahoo375.onmicrosoft.com

Sheet OrderDetails
A1: supplierid | B1: OrderID | C1: ShipperID | D1: ProdID | E1: EmpID | F1: Qty | G1: Discount | H1: AdminFees | I1: UnitPrice
A2: 48256 | B2: 69 | C2: 11 | D2: 106 | E2: A0001 | F2: 5 | G2: 0 | H2: =IF(F2<=10,RANDBETWEEN(1,5),IF(F2<=20,RANDBETWEEN(15,80),IF(F2<=30,RANDBETWEEN(23,150),RANDBETWEEN(66,350)))) -> 4 | I2: 48.36
A3: 86563 | B3: 18 | C3: 11 | D3: 108 | E3: C0011 | F3: 78 | G3: 0.1 | H3: =IF(F3<=10,RANDBETWEEN(1,5),IF(F3<=20,RANDBETWEEN(15,80),IF(F3<=30,RANDBETWEEN(23,150),RANDBETWEEN(66,350)))) -> 118 | I3: 84.15
A4: 96352 | B4: 33 | C4: 11 | D4: 101 | E4: A0001 | F4: 117 | G4: 0.25 | H4: =IF(F4<=10,RANDBETWEEN(1,5),IF(F4<=20,RANDBETWEEN(15,80),IF(F4<=30,RANDBETWEEN(23,150),RANDBETWEEN(66,350)))) -> 338 | I4: 30
A5: 48256 | B5: 61 | C5: 11 | D5: 102 | E5: E0013 | F5: 57 | G5: 0.1 | H5: =IF(F5<=10,RANDBETWEEN(1,5),IF(F5<=20,RANDBETWEEN(15,80),IF(F5<=30,RANDBETWEEN(23,150),RANDBETWEEN(66,350)))) -> 73 | I5: 41.08
A6: 96352 | B6: 45 | C6: 11 | D6: 103 | E6: C0005 | F6: 66 | G6: 0.1 | H6: =IF(F6<=10,RANDBETWEEN(1,5),IF(F6<=20,RANDBETWEEN(15,80),IF(F6<=30,RANDBETWEEN(23,150),RANDBETWEEN(66,350)))) -> 315 | I6: 55.04
A7: 96352 | B7: 11 | C7: 11 | D7: 102 | E7: B0101 | F7: 33 | G7: 0 | H7: =IF(F7<=10,RANDBETWEEN(1,5),IF(F7<=20,RANDBETWEEN(15,80),IF(F7<=30,RANDBETWEEN(23,150),RANDBETWEEN(66,350)))) -> 180 | I7: 96.8
A8: 96352 | B8: 62 | C8: 11 | D8: 109 | E8: B0101 | F8: 104 | G8: 0.25 | H8: =IF(F8<=10,RANDBETWEEN(1,5),IF(F8<=20,RANDBETWEEN(15,80),IF(F8<=30,RANDBETWEEN(23,150),RANDBETWEEN(66,350)))) -> 119 | I8: 63.6
A9: 96352 | B9: 30 | C9: 11 | D9: 106 | E9: C0005 | F9: 77 | G9: 0.1 | H9: =IF(F9<=10,RANDBETWEEN(1,5),IF(F9<=20,RANDBETWEEN(15,80),IF(F9<=30,RANDBETWEEN(23,150),RANDBETWEEN(66,350)))) -> 326 | I9: 77.85
A10: 48256 | B10: 2 | C10: 11 | D10: 109 | E10: C0002 | F10: 210 | G10: 0.25 | H10: =IF(F10<=10,RANDBETWEEN(1,5),IF(F10<=20,RANDBETWEEN(15,80),IF(F10<=30,RANDBETWEEN(23,150),RANDBETWEEN(66,350)))) -> 107 | I10: 70.14
A11: 96352 | B11: 31 | C11: 11 | D11: 108 | E11: C0002 | F11: 84 | G11: 0.25 | H11: =IF(F11<=10,RANDBETWEEN(1,5),IF(F11<=20,RANDBETWEEN(15,80),IF(F11<=30,RANDBETWEEN(23,150),RANDBETWEEN(66,350)))) -> 193 | I11: 70.98
A12: 96352 | B12: 1 | C12: 11 | D12: 109 | E12: E0012 | F12: 101 | G12: 0.25 | H12: =IF(F12<=10,RANDBETWEEN(1,5),IF(F12<=20,RANDBETWEEN(15,80),IF(F12<=30,RANDBETWEEN(23,150),RANDBETWEEN(66,350)))) -> 124 | I12: 28.5
A13: 86563 | B13: 14 | C13: 11 | D13: 103 | E13: C0020 | F13: 72 | G13: 0.1 | H13: =IF(F13<=10,RANDBETWEEN(1,5),IF(F13<=20,RANDBETWEEN(15,80),IF(F13<=30,RANDBETWEEN(23,150),RANDBETWEEN(66,350)))) -> 152 | I13: 46.76
... A368: 86563 | B368: 18 | C368: 12 | D368: 105 | E368: B0101 | F368: 18 | G368: 0 | H368: =IF(F368<=10,RANDBETWEEN(1,5),IF(F368<=20,RANDBETWEEN(15,80),IF(F368<=30,RANDBETWEEN(23,150),RANDBETWEEN(66,350)))) -> 61 | I368: 32.8
A369: =VLOOKUP(RANDBETWEEN(1,3),Suppliers!$A$2:$B$4,2) -> 86563 | B369: 51 | C369: =RANDBETWEEN(MIN(Shippers!$B$2:$B$9),MAX(Shippers!$B$2:$B$9)) -> 13 | D369: =RANDBETWEEN(MIN(Products!$B$2:$B$9),MAX(Products!$B$2:$B$9)) -> 104 | E369: E0013 | F369: =RANDBETWEEN(1,250) -> 61 | G369: =VLOOKUP(RANDBETWEEN(1,3),RandomNList!$Z$3:$AA$5,2) -> 0 | H369: =IF(F369<=10,RANDBETWEEN(1,5),IF(F369<=20,RANDBETWEEN(15,80),IF(F369<=30,RANDBETWEEN(23,150),RANDBETWEEN(66,350)))) -> 83 | I369: 43.75
A370: 96352 | B370: 1 | C370: 13 | D370: 105 | E370: B0101 | F370: 95 | G370: 0.25 | H370: =IF(F370<=10,RANDBETWEEN(1,5),IF(F370<=20,RANDBETWEEN(15,80),IF(F370<=30,RANDBETWEEN(23,150),RANDBETWEEN(66,350)))) -> 261 | I370: 57.66
A371: 96352 | B371: 42 | C371: 13 | D371: 106 | E371: C0003 | F371: 56 | G371: 0.1 | H371: =IF(F371<=10,RANDBETWEEN(1,5),IF(F371<=20,RANDBETWEEN(15,80),IF(F371<=30,RANDBETWEEN(23,150),RANDBETWEEN(66,350)))) -> 333 | I371: 105.84
A372: 48256 | B372: 40 | C372: 13 | D372: 103 | E372: C0005 | F372: 121 | G372: 0.25 | H372: =IF(F372<=10,RANDBETWEEN(1,5),IF(F372<=20,RANDBETWEEN(15,80),IF(F372<=30,RANDBETWEEN(23,150),RANDBETWEEN(66,350)))) -> 232 | I372: 37.03
A373: 96352 | B373: 49 | C373: 13 | D373: 108 | E373: C0005 | F373: 6 | G373: 0 | H373: =IF(F373<=10,RANDBETWEEN(1,5),IF(F373<=20,RANDBETWEEN(15,80),IF(F373<=30,RANDBETWEEN(23,150),RANDBETWEEN(66,350)))) -> 5 | I373: 16.8
A374: 96352 | B374: 64 | C374: 13 | D374: 107 | E374: C0020 | F374: 23 | G374: 0 | H374: =IF(F374<=10,RANDBETWEEN(1,5),IF(F374<=20,RANDBETWEEN(15,80),IF(F374<=30,RANDBETWEEN(23,150),RANDBETWEEN(66,350)))) -> 141 | I374: 105.56
A375: 96352 | B375: 58 | C375: 13 | D375: 101 | E375: C0020 | F375: 32 | G375: 0 | H375: =IF(F375<=10,RANDBETWEEN(1,5),IF(F375<=20,RANDBETWEEN(15,80),IF(F375<=30,RANDBETWEEN(23,150),RANDBETWEEN(66,350)))) -> 237 | I375: 34.01
A376: 96352 | B376: 46 | C376: 13 | D376: 109 | E376: C0011 | F376: 23 | G376: 0 | H376: =IF(F376<=10,RANDBETWEEN(1,5),IF(F376<=20,RANDBETWEEN(15,80),IF(F376<=30,RANDBETWEEN(23,150),RANDBETWEEN(66,350)))) -> 58 | I376: 68.4
A377: 48256 | B377: 56 | C377: 13 | D377: 105 | E377: E0001 | F377: 50 | G377: 0 | H377: =IF(F377<=10,RANDBETWEEN(1,5),IF(F377<=20,RANDBETWEEN(15,80),IF(F377<=30,RANDBETWEEN(23,150),RANDBETWEEN(66,350)))) -> 150 | I377: 87.58
A378: 86563 | B378: 17 | C378: 13 | D378: 101 | E378: E0001 | F378: 78 | G378: 0.1 | H378: =IF(F378<=10,RANDBETWEEN(1,5),IF(F378<=20,RANDBETWEEN(15,80),IF(F378<=30,RANDBETWEEN(23,150),RANDBETWEEN(66,350)))) -> 240 | I378: 75.24
A379: 96352 | B379: 63 | C379: 13 | D379: 107 | E379: C0003 | F379: 109 | G379: 0.25 | H379: =IF(F379<=10,RANDBETWEEN(1,5),IF(F379<=20,RANDBETWEEN(15,80),IF(F379<=30,RANDBETWEEN(23,150),RANDBETWEEN(66,350)))) -> 184 | I379: 48.6
A380: 48256 | B380: 32 | C380: 13 | D380: 104 | E380: E0001 | F380: 118 | G380: 0.25 | H380: =IF(F380<=10,RANDBETWEEN(1,5),IF(F380<=20,RANDBETWEEN(15,80),IF(F380<=30,RANDBETWEEN(23,150),RANDBETWEEN(66,350)))) -> 99 | I380: 17.05
A381: 86563 | B381: 10 | C381: 13 | D381: 106 | E381: C0003 | F381: 26 | G381: 0 | H381: =IF(F381<=10,RANDBETWEEN(1,5),IF(F381<=20,RANDBETWEEN(15,80),IF(F381<=30,RANDBETWEEN(23,150),RANDBETWEEN(66,350)))) -> 90 | I381: 80.58
... A905: 86563 | B905: 63 | C905: 15 | D905: 108 | E905: E0013 | F905: 64 | G905: 0.1 | H905: =IF(F905<=10,RANDBETWEEN(1,5),IF(F905<=20,RANDBETWEEN(15,80),IF(F905<=30,RANDBETWEEN(23,150),RANDBETWEEN(66,350)))) -> 231 | I905: 65.36

Sheet Products
A1: no | B1: productid | C1: productname | D1: SalesPrice | E1: CostPrice | F1: ingredient1 | G1: ingredient2 | H1: suppid
A2: 1 | B2: 101 | C2: Choco Banana Split | D2: 23 | E2: 9.95 | F2: Banana | G2: Chocolate | H2: 86563
A3: 2 | B3: 102 | C3: Body Builder Juice | D3: 15 | E3: 13.95 | F3: Passion fruit | G3: Mango | H3: 96352
A4: 3 | B4: 103 | C4: Pink Passion Juice | D4: 28 | E4: 15 | F4: Passion fruit | G4: Guava | H4: 48256
A5: 4 | B5: 104 | C5: Durian Milk Shakes | D5: 5.9 | E5: 2.9 | F5: Durian | G5: Milk | H5: 96352
A6: 5 | B6: 105 | C6: Green Apple Shakes | D6: 15 | E6: 10 | F6: Apple | G6: Orange | H6: 86563
A7: 6 | B7: 106 | C7: Dragon Sparkle Drink | D7: 25 | E7: 9.1 | F7: Apple | G7: Guava | H7: 96352
A8: 7 | B8: 107 | C8: Sprite Shakes | D8: 15 | E8: 5.5 | F8: Passion fruit | G8: Milk | H8: 96352
A9: 8 | B9: 108 | C9: Fruitee Delight | D9: 5.5 | E9: 3.99 | F9: Banana | G9: Apple | H9: 48256
A10: 9 | B10: 109 | C10: Mango Delight | D10: 36 | E10: 16.8 | F10: Mango | G10: Milk | H10: 86563
A11: 10 | B11: 110 | C11: Fusion Mango Wombo | D11: 51.5 | E11: 20.5 | F11: Passion fruit | G11: Mango | H11: 86563

Sheet Cloud-AWS
A1: UID | B1: Machine Model | C1: Type | D1: Country | E1: Continent | F1: Region | G1: CPU-min | H1: CPU-max | I1: MEM-min | J1: MEM-max | K1: MultiplyF | L1: Price-min | M1: Price-max
A2: =B2&LEFT(C2,1)&LEFT(D2,1)&RIGHT(D2,1) -> C00104CAa | B2: =LEFT(C2,1)&"00"&G2&I2 -> C00104 | C2: Compute Optimized | D2: Argentina | E2: =VLOOKUP(D2,countrylist[[countryname]:[region]],4) -> South America | F2: =VLOOKUP(D2,countrylist[[countryname]:[region]],5) -> South America | G2: 10 | H2: 20 | I2: 4 | J2: 6 | K2: 2 | L2: =(RANDBETWEEN(600,700)*K2) -> 1336 | M2: =(RANDBETWEEN(800,900)*K2) -> 1748
A3: =B3&LEFT(C3,1)&LEFT(D3,1)&RIGHT(D3,1) -> C00104CCa | B3: =LEFT(C3,1)&"00"&G3&I3 -> C00104 | C3: Compute Optimized | D3: Canada | E3: =VLOOKUP(D3,countrylist[[countryname]:[region]],4) -> North America | F3: =VLOOKUP(D3,countrylist[[countryname]:[region]],5) -> Northern America | G3: 10 | H3: 20 | I3: 4 | J3: 6 | K3: 2 | L3: =(RANDBETWEEN(600,700)*K3) -> 1350 | M3: =(RANDBETWEEN(800,900)*K3) -> 1756
A4: =B4&LEFT(C4,1)&LEFT(D4,1)&RIGHT(D4,1) -> C00104CDk | B4: =LEFT(C4,1)&"00"&G4&I4 -> C00104 | C4: Compute Optimized | D4: Denmark | E4: =VLOOKUP(D4,countrylist[[countryname]:[region]],4) -> Europe | F4: =VLOOKUP(D4,countrylist[[countryname]:[region]],5) -> Northern Europe | G4: 10 | H4: 20 | I4: 4 | J4: 6 | K4: 2 | L4: =(RANDBETWEEN(600,700)*K4) -> 1232 | M4: =(RANDBETWEEN(800,900)*K4) -> 1648
A5: =B5&LEFT(C5,1)&LEFT(D5,1)&RIGHT(D5,1) -> C00104CGy | B5: =LEFT(C5,1)&"00"&G5&I5 -> C00104 | C5: Compute Optimized | D5: Germany | E5: =VLOOKUP(D5,countrylist[[countryname]:[region]],4) -> Europe | F5: =VLOOKUP(D5,countrylist[[countryname]:[region]],5) -> Western Europe | G5: 10 | H5: 20 | I5: 4 | J5: 6 | K5: 5 | L5: =(RANDBETWEEN(600,700)*K5) -> 3410 | M5: =(RANDBETWEEN(800,900)*K5) -> 4220
A6: =B6&LEFT(C6,1)&LEFT(D6,1)&RIGHT(D6,1) -> C00104CLa | B6: =LEFT(C6,1)&"00"&G6&I6 -> C00104 | C6: Compute Optimized | D6: Latvia | E6: =VLOOKUP(D6,countrylist[[countryname]:[region]],4) -> Europe | F6: =VLOOKUP(D6,countrylist[[countryname]:[region]],5) -> Northern Europe | G6: 10 | H6: 20 | I6: 4 | J6: 6 | K6: 1.5 | L6: =(RANDBETWEEN(600,700)*K6) -> 1026 | M6: =(RANDBETWEEN(800,900)*K6) -> 1315.5
A7: =B7&LEFT(C7,1)&LEFT(D7,1)&RIGHT(D7,1) -> C00104CMa | B7: =LEFT(C7,1)&"00"&G7&I7 -> C00104 | C7: Compute Optimized | D7: Malaysia | E7: =VLOOKUP(D7,countrylist[[countryname]:[region]],4) -> Asia | F7: =VLOOKUP(D7,countrylist[[countryname]:[region]],5) -> South-eastern Asia | G7: 10 | H7: 20 | I7: 4 | J7: 6 | K7: 1 | L7: =(RANDBETWEEN(600,700)*K7) -> 606 | M7: =(RANDBETWEEN(800,900)*K7) -> 866
A8: =B8&LEFT(C8,1)&LEFT(D8,1)&RIGHT(D8,1) -> C00104CSe | B8: =LEFT(C8,1)&"00"&G8&I8 -> C00104 | C8: Compute Optimized | D8: Singapore | E8: =VLOOKUP(D8,countrylist[[countryname]:[region]],4) -> Asia | F8: =VLOOKUP(D8,countrylist[[countryname]:[region]],5) -> South-eastern Asia | G8: 10 | H8: 20 | I8: 4 | J8: 6 | K8: 2 | L8: =(RANDBETWEEN(600,700)*K8) -> 1276 | M8: =(RANDBETWEEN(800,900)*K8) -> 1634
A9: =B9&LEFT(C9,1)&LEFT(D9,1)&RIGHT(D9,1) -> C00104CSn | B9: =LEFT(C9,1)&"00"&G9&I9 -> C00104 | C9: Compute Optimized | D9: Spain | E9: =VLOOKUP(D9,countrylist[[countryname]:[region]],4) -> Europe | F9: =VLOOKUP(D9,countrylist[[countryname]:[region]],5) -> Southern Europe | G9: 10 | H9: 20 | I9: 4 | J9: 6 | K9: 3.5 | L9: =(RANDBETWEEN(600,700)*K9) -> 2289 | M9: =(RANDBETWEEN(800,900)*K9) -> 2933
A10: =B10&LEFT(C10,1)&LEFT(D10,1)&RIGHT(D10,1) -> C00104CTd | B10: =LEFT(C10,1)&"00"&G10&I10 -> C00104 | C10: Compute Optimized | D10: Thailand | E10: =VLOOKUP(D10,countrylist[[countryname]:[region]],4) -> Asia | F10: =VLOOKUP(D10,countrylist[[countryname]:[region]],5) -> South-eastern Asia | G10: 10 | H10: 20 | I10: 4 | J10: 6 | K10: 1.5 | L10: =(RANDBETWEEN(600,700)*K10) -> 954 | M10: =(RANDBETWEEN(800,900)*K10) -> 1336.5
A11: =B11&LEFT(C11,1)&LEFT(D11,1)&RIGHT(D11,1) -> C00104CTe | B11: =LEFT(C11,1)&"00"&G11&I11 -> C00104 | C11: Compute Optimized | D11: Turkeye | E11: =VLOOKUP(D11,countrylist[[countryname]:[region]],4) -> Asia | F11: =VLOOKUP(D11,countrylist[[countryname]:[region]],5) -> Western Asia | G11: 10 | H11: 20 | I11: 4 | J11: 6 | K11: 0.5 | L11: =(RANDBETWEEN(600,700)*K11) -> 305.5 | M11: =(RANDBETWEEN(800,900)*K11) -> 406.5
A12: =B12&LEFT(C12,1)&LEFT(D12,1)&RIGHT(D12,1) -> C00104CVm | B12: =LEFT(C12,1)&"00"&G12&I12 -> C00104 | C12: Compute Optimized | D12: Vietnam | E12: =VLOOKUP(D12,countrylist[[countryname]:[region]],4) -> Asia | F12: =VLOOKUP(D12,countrylist[[countryname]:[region]],5) -> South-eastern Asia | G12: 10 | H12: 20 | I12: 4 | J12: 6 | K12: 2 | L12: =(RANDBETWEEN(600,700)*K12) -> 1272 | M12: =(RANDBETWEEN(800,900)*K12) -> 1754
A13: =B13&LEFT(C13,1)&LEFT(D13,1)&RIGHT(D13,1) -> G0011GCa | B13: =LEFT(C13,1)&"00"&G13&I13 -> G0011 | C13: General Purpose | D13: Canada | E13: =VLOOKUP(D13,countrylist[[countryname]:[region]],4) -> North America | F13: =VLOOKUP(D13,countrylist[[countryname]:[region]],5) -> Northern America | G13: 1 | H13: 3 | I13: 1 | J13: 3 | K13: 2 | L13: =(RANDBETWEEN(600,700)*K13) -> 1258 | M13: =(RANDBETWEEN(800,900)*K13) -> 1774
... A70: =B70&LEFT(C70,1)&LEFT(D70,1)&RIGHT(D70,1) -> H003010HVm | B70: =LEFT(C70,1)&"00"&G70&I70 -> H003010 | C70: HPC Optimized | D70: Vietnam | E70: =VLOOKUP(D70,countrylist[[countryname]:[region]],4) -> Asia | F70: =VLOOKUP(D70,countrylist[[countryname]:[region]],5) -> South-eastern Asia | G70: 30 | H70: 40 | I70: 10 | J70: 30 | K70: 6 | L70: =(RANDBETWEEN(600,700)*K70) -> 4176 | M70: =(RANDBETWEEN(800,900)*K70) -> 4836

Sheet Cloud-Azure
A1: UID | B1: Machine Model | C1: Type | D1: Country | E1: Continent | F1: Region | G1: CPU-min | H1: CPU-max | I1: MEM-min | J1: MEM-max | K1: MultiplyF | L1: Price-min | M1: Price-max
A2: =B2&LEFT(C2,1)&LEFT(D2,1)&RIGHT(D2,1) -> AZ101EFe | B2: AZ101 | C2: Entry | D2: France | E2: =VLOOKUP(D2,countrylist[[countryname]:[region]],4) -> Europe | F2: =VLOOKUP(D2,countrylist[[countryname]:[region]],5) -> Western Europe | G2: 1 | H2: 3 | I2: 1 | J2: 3 | K2: 1 | L2: =(RANDBETWEEN(600,700)*K2) -> 642 | M2: =(RANDBETWEEN(800,900)*K2) -> 859
A3: =B3&LEFT(C3,1)&LEFT(D3,1)&RIGHT(D3,1) -> AZ103MFe | B3: AZ103 | C3: Memory Optimized | D3: France | E3: =VLOOKUP(D3,countrylist[[countryname]:[region]],4) -> Europe | F3: =VLOOKUP(D3,countrylist[[countryname]:[region]],5) -> Western Europe | G3: 4 | H3: 10 | I3: 10 | J3: 20 | K3: 2 | L3: =(RANDBETWEEN(600,700)*K3) -> 1370 | M3: =(RANDBETWEEN(800,900)*K3) -> 1710
A4: =B4&LEFT(C4,1)&LEFT(D4,1)&RIGHT(D4,1) -> AZ105GFe | B4: AZ105 | C4: GPU Optimized | D4: France | E4: =VLOOKUP(D4,countrylist[[countryname]:[region]],4) -> Europe | F4: =VLOOKUP(D4,countrylist[[countryname]:[region]],5) -> Western Europe | G4: 2 | H4: 5 | I4: 2 | J4: 5 | K4: 3 | L4: =(RANDBETWEEN(600,700)*K4) -> 1860 | M4: =(RANDBETWEEN(800,900)*K4) -> 2553
A5: =B5&LEFT(C5,1)&LEFT(D5,1)&RIGHT(D5,1) -> AZ106NFe | B5: AZ106 | C5: Network Optimized | D5: France | E5: =VLOOKUP(D5,countrylist[[countryname]:[region]],4) -> Europe | F5: =VLOOKUP(D5,countrylist[[countryname]:[region]],5) -> Western Europe | G5: 1 | H5: 3 | I5: 1 | J5: 3 | K5: 3 | L5: =(RANDBETWEEN(600,700)*K5) -> 2031 | M5: =(RANDBETWEEN(800,900)*K5) -> 2553
A6: =B6&LEFT(C6,1)&LEFT(D6,1)&RIGHT(D6,1) -> AZ102MIa | B6: AZ102 | C6: Mid range | D6: Indonesia | E6: =VLOOKUP(D6,countrylist[[countryname]:[region]],4) -> Asia | F6: =VLOOKUP(D6,countrylist[[countryname]:[region]],5) -> South-eastern Asia | G6: 4 | H6: 6 | I6: 4 | J6: 6 | K6: 1 | L6: =(RANDBETWEEN(600,700)*K6) -> 655 | M6: =(RANDBETWEEN(800,900)*K6) -> 877
A7: =B7&LEFT(C7,1)&LEFT(D7,1)&RIGHT(D7,1) -> AZ101EJn | B7: AZ101 | C7: Entry | D7: Japan | E7: =VLOOKUP(D7,countrylist[[countryname]:[region]],4) -> Asia | F7: =VLOOKUP(D7,countrylist[[countryname]:[region]],5) -> Eastern Asia | G7: 1 | H7: 3 | I7: 1 | J7: 3 | K7: 3 | L7: =(RANDBETWEEN(600,700)*K7) -> 1851 | M7: =(RANDBETWEEN(800,900)*K7) -> 2601
A8: =B8&LEFT(C8,1)&LEFT(D8,1)&RIGHT(D8,1) -> AZ102MJn | B8: AZ102 | C8: Mid range | D8: Japan | E8: =VLOOKUP(D8,countrylist[[countryname]:[region]],4) -> Asia | F8: =VLOOKUP(D8,countrylist[[countryname]:[region]],5) -> Eastern Asia | G8: 4 | H8: 6 | I8: 4 | J8: 6 | K8: 3 | L8: =(RANDBETWEEN(600,700)*K8) -> 1896 | M8: =(RANDBETWEEN(800,900)*K8) -> 2445
A9: =B9&LEFT(C9,1)&LEFT(D9,1)&RIGHT(D9,1) -> AZ101EMa | B9: AZ101 | C9: Entry | D9: Malaysia | E9: =VLOOKUP(D9,countrylist[[countryname]:[region]],4) -> Asia | F9: =VLOOKUP(D9,countrylist[[countryname]:[region]],5) -> South-eastern Asia | G9: 1 | H9: 3 | I9: 1 | J9: 3 | K9: 1 | L9: =(RANDBETWEEN(600,700)*K9) -> 601 | M9: =(RANDBETWEEN(800,900)*K9) -> 824
A10: =B10&LEFT(C10,1)&LEFT(D10,1)&RIGHT(D10,1) -> AZ102MMa | B10: AZ102 | C10: Mid range | D10: Malaysia | E10: =VLOOKUP(D10,countrylist[[countryname]:[region]],4) -> Asia | F10: =VLOOKUP(D10,countrylist[[countryname]:[region]],5) -> South-eastern Asia | G10: 4 | H10: 6 | I10: 4 | J10: 6 | K10: 1 | L10: =(RANDBETWEEN(600,700)*K10) -> 625 | M10: =(RANDBETWEEN(800,900)*K10) -> 871
A11: =B11&LEFT(C11,1)&LEFT(D11,1)&RIGHT(D11,1) -> AZ103MMa | B11: AZ103 | C11: Memory Optimized | D11: Malaysia | E11: =VLOOKUP(D11,countrylist[[countryname]:[region]],4) -> Asia | F11: =VLOOKUP(D11,countrylist[[countryname]:[region]],5) -> South-eastern Asia | G11: 4 | H11: 10 | I11: 10 | J11: 20 | K11: 1 | L11: =(RANDBETWEEN(600,700)*K11) -> 617 | M11: =(RANDBETWEEN(800,900)*K11) -> 835
A12: =B12&LEFT(C12,1)&LEFT(D12,1)&RIGHT(D12,1) -> AZ104CMa | B12: AZ104 | C12: CPU Optimized | D12: Malaysia | E12: =VLOOKUP(D12,countrylist[[countryname]:[region]],4) -> Asia | F12: =VLOOKUP(D12,countrylist[[countryname]:[region]],5) -> South-eastern Asia | G12: 10 | H12: 20 | I12: 4 | J12: 6 | K12: 1 | L12: =(RANDBETWEEN(600,700)*K12) -> 647 | M12: =(RANDBETWEEN(800,900)*K12) -> 826
A13: =B13&LEFT(C13,1)&LEFT(D13,1)&RIGHT(D13,1) -> AZ106NMa | B13: AZ106 | C13: Network Optimized | D13: Malaysia | E13: =VLOOKUP(D13,countrylist[[countryname]:[region]],4) -> Asia | F13: =VLOOKUP(D13,countrylist[[countryname]:[region]],5) -> South-eastern Asia | G13: 1 | H13: 3 | I13: 1 | J13: 3 | K13: 1 | L13: =(RANDBETWEEN(600,700)*K13) -> 692 | M13: =(RANDBETWEEN(800,900)*K13) -> 849
... A70: =B70&LEFT(C70,1)&LEFT(D70,1)&RIGHT(D70,1) -> AZ106NCe | B70: AZ106 | C70: Network Optimized | D70: Chile | E70: =VLOOKUP(D70,countrylist[[countryname]:[region]],4) -> South America | F70: =VLOOKUP(D70,countrylist[[countryname]:[region]],5) -> South America | G70: 1 | H70: 3 | I70: 1 | J70: 3 | K70: 2 | L70: =(RANDBETWEEN(600,700)*K70) -> 1222 | M70: =(RANDBETWEEN(800,900)*K70) -> 1742

Sheet Cloud-Google
A1: UID | B1: Machine Model | C1: Type | D1: Country | E1: Continent | F1: Region | G1: CPU-min | H1: CPU-max | I1: MEM-min | J1: MEM-max | K1: MultiplyF | L1: Price-min | M1: Price-max
A2: =B2&LEFT(C2,1)&LEFT(D2,1)&RIGHT(D2,1) -> E0011EAa | B2: =LEFT(C2,1)&"00"&G2&I2 -> E0011 | C2: Entry | D2: Argentina | E2: =VLOOKUP(D2,countrylist[[countryname]:[region]],4) -> South America | F2: =VLOOKUP(D2,countrylist[[countryname]:[region]],5) -> South America | G2: 1 | H2: 3 | I2: 1 | J2: 3 | K2: 2 | L2: =(RANDBETWEEN(600,700)*K2) -> 1258 | M2: =(RANDBETWEEN(800,900)*K2) -> 1736
A3: =B3&LEFT(C3,1)&LEFT(D3,1)&RIGHT(D3,1) -> M0044MAa | B3: =LEFT(C3,1)&"00"&G3&I3 -> M0044 | C3: Mid range | D3: Argentina | E3: =VLOOKUP(D3,countrylist[[countryname]:[region]],4) -> South America | F3: =VLOOKUP(D3,countrylist[[countryname]:[region]],5) -> South America | G3: 4 | H3: 6 | I3: 4 | J3: 6 | K3: 2 | L3: =(RANDBETWEEN(600,700)*K3) -> 1236 | M3: =(RANDBETWEEN(800,900)*K3) -> 1606
A4: =B4&LEFT(C4,1)&LEFT(D4,1)&RIGHT(D4,1) -> M00410MAa | B4: =LEFT(C4,1)&"00"&G4&I4 -> M00410 | C4: Memory Optimized | D4: Argentina | E4: =VLOOKUP(D4,countrylist[[countryname]:[region]],4) -> South America | F4: =VLOOKUP(D4,countrylist[[countryname]:[region]],5) -> South America | G4: 4 | H4: 10 | I4: 10 | J4: 20 | K4: 2 | L4: =(RANDBETWEEN(600,700)*K4) -> 1308 | M4: =(RANDBETWEEN(800,900)*K4) -> 1740
A5: =B5&LEFT(C5,1)&LEFT(D5,1)&RIGHT(D5,1) -> C00104CAa | B5: =LEFT(C5,1)&"00"&G5&I5 -> C00104 | C5: CPU Optimized | D5: Argentina | E5: =VLOOKUP(D5,countrylist[[countryname]:[region]],4) -> South America | F5: =VLOOKUP(D5,countrylist[[countryname]:[region]],5) -> South America | G5: 10 | H5: 20 | I5: 4 | J5: 6 | K5: 2 | L5: =(RANDBETWEEN(600,700)*K5) -> 1276 | M5: =(RANDBETWEEN(800,900)*K5) -> 1620
A6: =B6&LEFT(C6,1)&LEFT(D6,1)&RIGHT(D6,1) -> N0011NAa | B6: =LEFT(C6,1)&"00"&G6&I6 -> N0011 | C6: Network Optimized | D6: Argentina | E6: =VLOOKUP(D6,countrylist[[countryname]:[region]],4) -> South America | F6: =VLOOKUP(D6,countrylist[[countryname]:[region]],5) -> South America | G6: 1 | H6: 3 | I6: 1 | J6: 3 | K6: 2 | L6: =(RANDBETWEEN(600,700)*K6) -> 1200 | M6: =(RANDBETWEEN(800,900)*K6) -> 1646
A7: =B7&LEFT(C7,1)&LEFT(D7,1)&RIGHT(D7,1) -> E0011ECa | B7: =LEFT(C7,1)&"00"&G7&I7 -> E0011 | C7: Entry | D7: Canada | E7: =VLOOKUP(D7,countrylist[[countryname]:[region]],4) -> North America | F7: =VLOOKUP(D7,countrylist[[countryname]:[region]],5) -> Northern America | G7: 1 | H7: 3 | I7: 1 | J7: 3 | K7: 2 | L7: =(RANDBETWEEN(600,700)*K7) -> 1400 | M7: =(RANDBETWEEN(800,900)*K7) -> 1624
A8: =B8&LEFT(C8,1)&LEFT(D8,1)&RIGHT(D8,1) -> M0044MCa | B8: =LEFT(C8,1)&"00"&G8&I8 -> M0044 | C8: Mid range | D8: Canada | E8: =VLOOKUP(D8,countrylist[[countryname]:[region]],4) -> North America | F8: =VLOOKUP(D8,countrylist[[countryname]:[region]],5) -> Northern America | G8: 4 | H8: 6 | I8: 4 | J8: 6 | K8: 2 | L8: =(RANDBETWEEN(600,700)*K8) -> 1210 | M8: =(RANDBETWEEN(800,900)*K8) -> 1754
A9: =B9&LEFT(C9,1)&LEFT(D9,1)&RIGHT(D9,1) -> M00410MCa | B9: =LEFT(C9,1)&"00"&G9&I9 -> M00410 | C9: Memory Optimized | D9: Canada | E9: =VLOOKUP(D9,countrylist[[countryname]:[region]],4) -> North America | F9: =VLOOKUP(D9,countrylist[[countryname]:[region]],5) -> Northern America | G9: 4 | H9: 10 | I9: 10 | J9: 20 | K9: 2 | L9: =(RANDBETWEEN(600,700)*K9) -> 1276 | M9: =(RANDBETWEEN(800,900)*K9) -> 1614
A10: =B10&LEFT(C10,1)&LEFT(D10,1)&RIGHT(D10,1) -> C00104CCa | B10: =LEFT(C10,1)&"00"&G10&I10 -> C00104 | C10: CPU Optimized | D10: Canada | E10: =VLOOKUP(D10,countrylist[[countryname]:[region]],4) -> North America | F10: =VLOOKUP(D10,countrylist[[countryname]:[region]],5) -> Northern America | G10: 10 | H10: 20 | I10: 4 | J10: 6 | K10: 2 | L10: =(RANDBETWEEN(600,700)*K10) -> 1368 | M10: =(RANDBETWEEN(800,900)*K10) -> 1704
A11: =B11&LEFT(C11,1)&LEFT(D11,1)&RIGHT(D11,1) -> N0011NCa | B11: =LEFT(C11,1)&"00"&G11&I11 -> N0011 | C11: Network Optimized | D11: Canada | E11: =VLOOKUP(D11,countrylist[[countryname]:[region]],4) -> North America | F11: =VLOOKUP(D11,countrylist[[countryname]:[region]],5) -> Northern America | G11: 1 | H11: 3 | I11: 1 | J11: 3 | K11: 2 | L11: =(RANDBETWEEN(600,700)*K11) -> 1376 | M11: =(RANDBETWEEN(800,900)*K11) -> 1630
A12: =B12&LEFT(C12,1)&LEFT(D12,1)&RIGHT(D12,1) -> E0011EDk | B12: =LEFT(C12,1)&"00"&G12&I12 -> E0011 | C12: Entry | D12: Denmark | E12: =VLOOKUP(D12,countrylist[[countryname]:[region]],4) -> Europe | F12: =VLOOKUP(D12,countrylist[[countryname]:[region]],5) -> Northern Europe | G12: 1 | H12: 3 | I12: 1 | J12: 3 | K12: 2 | L12: =(RANDBETWEEN(600,700)*K12) -> 1396 | M12: =(RANDBETWEEN(800,900)*K12) -> 1756
A13: =B13&LEFT(C13,1)&LEFT(D13,1)&RIGHT(D13,1) -> M0044MDk | B13: =LEFT(C13,1)&"00"&G13&I13 -> M0044 | C13: Mid range | D13: Denmark | E13: =VLOOKUP(D13,countrylist[[countryname]:[region]],4) -> Europe | F13: =VLOOKUP(D13,countrylist[[countryname]:[region]],5) -> Northern Europe | G13: 4 | H13: 6 | I13: 4 | J13: 6 | K13: 2 | L13: =(RANDBETWEEN(600,700)*K13) -> 1360 | M13: =(RANDBETWEEN(800,900)*K13) -> 1682
... A70: =B70&LEFT(C70,1)&LEFT(D70,1)&RIGHT(D70,1) -> N0011NVm | B70: =LEFT(C70,1)&"00"&G70&I70 -> N0011 | C70: Network Optimized | D70: Vietnam | E70: =VLOOKUP(D70,countrylist[[countryname]:[region]],4) -> Asia | F70: =VLOOKUP(D70,countrylist[[countryname]:[region]],5) -> South-eastern Asia | G70: 1 | H70: 3 | I70: 1 | J70: 3 | K70: 2 | L70: =(RANDBETWEEN(600,700)*K70) -> 1384 | M70: =(RANDBETWEEN(800,900)*K70) -> 1670

Sheet K8s Resources
A1: Object | B1: JSON | C1: XML | D1: Assig to | E1: Sensational
A2: PV | B2: { "apiVersion": "v1", "kind": "PersistentVolume", "metadata": { "name": "example-pv", "labels": { "type": "local" } | C2: apiVersion: v1 kind: PersistentVolumeClaim metadata: name: foo-pvc namespace: foo spec: storageClassName: "" # Empty string must be explicitly set otherwise default StorageClass will be set volumeName: foo-pv | D2: test-pod:running:1/2:nginx-1.28
A3: POD | B3: { "apiVersion": "v1", "kind": "Pod", "metadata": { "name": "my-first-pod", "labels": { "app": "example" } }, "spec": { "containers": [ { "name": "busybox", "image": "busybox:latest", "command": ["sleep", "3600"] } ] } } | C3: apiVersion: v1 kind: Pod metadata: name: nginx spec: containers: - name: nginx image: nginx:1.14.2 ports: - containerPort: 80 | D3: web-pod:running:3/3:apache-2.18.4

Sheet SalesByCountry
A1: Segment | B1: Country | C1: productid | D1: Discount Band | E1: Units Sold | F1: Sale Price | G1: Gross Sales | H1: Discounts | I1: Net Sales | J1: COGS | K1: Profit | L1: Sales Date | M1: Salesperson
A2: Government | B2: Philipines | C2: 106 | D2: Low | E2: 13 | F2: =VLOOKUP(financials[[#This Row],[productid]],Products!$B$2:$H$10,3) -> 25 | G2: =financials[[#This Row],[Units Sold]]*financials[[#This Row],[Sale Price]] -> 325 | H2: =IF(financials[[#This Row],[Discount Band]]="low",0.1,IF(financials[[#This Row],[Discount Band]]="medium",0.15,0.3)) -> 0.1 | I2: =financials[[#This Row],[Gross Sales]]-financials[[#This Row],[Gross Sales]]*financials[[#This Row],[Discounts]] -> 292.5 | J2: =VLOOKUP(financials[[#This Row],[productid]],Products!$B$2:$H$10,4) -> 9.1 | K2: =financials[[#This Row],[Net Sales]]-financials[[#This Row],[COGS]] -> 283.4 | L2: 44405 | M2: C0002
A3: Government | B3: Philipines | C3: 102 | D3: Medium | E3: 15 | F3: =VLOOKUP(financials[[#This Row],[productid]],Products!$B$2:$H$10,3) -> 15 | G3: =financials[[#This Row],[Units Sold]]*financials[[#This Row],[Sale Price]] -> 225 | H3: =IF(financials[[#This Row],[Discount Band]]="low",0.1,IF(financials[[#This Row],[Discount Band]]="medium",0.15,0.3)) -> 0.15 | I3: =financials[[#This Row],[Gross Sales]]-financials[[#This Row],[Gross Sales]]*financials[[#This Row],[Discounts]] -> 191.25 | J3: =VLOOKUP(financials[[#This Row],[productid]],Products!$B$2:$H$10,4) -> 13.95 | K3: =financials[[#This Row],[Net Sales]]-financials[[#This Row],[COGS]] -> 177.3 | L3: 45089 | M3: C0002
A4: Government | B4: Philipines | C4: 103 | D4: Medium | E4: 15 | F4: =VLOOKUP(financials[[#This Row],[productid]],Products!$B$2:$H$10,3) -> 28 | G4: =financials[[#This Row],[Units Sold]]*financials[[#This Row],[Sale Price]] -> 420 | H4: =IF(financials[[#This Row],[Discount Band]]="low",0.1,IF(financials[[#This Row],[Discount Band]]="medium",0.15,0.3)) -> 0.15 | I4: =financials[[#This Row],[Gross Sales]]-financials[[#This Row],[Gross Sales]]*financials[[#This Row],[Discounts]] -> 357 | J4: =VLOOKUP(financials[[#This Row],[productid]],Products!$B$2:$H$10,4) -> 15 | K4: =financials[[#This Row],[Net Sales]]-financials[[#This Row],[COGS]] -> 342 | L4: 45188 | M4: A0001
A5: Government | B5: Philipines | C5: 105 | D5: High | E5: 11 | F5: =VLOOKUP(financials[[#This Row],[productid]],Products!$B$2:$H$10,3) -> 15 | G5: =financials[[#This Row],[Units Sold]]*financials[[#This Row],[Sale Price]] -> 165 | H5: =IF(financials[[#This Row],[Discount Band]]="low",0.1,IF(financials[[#This Row],[Discount Band]]="medium",0.15,0.3)) -> 0.3 | I5: =financials[[#This Row],[Gross Sales]]-financials[[#This Row],[Gross Sales]]*financials[[#This Row],[Discounts]] -> 115.5 | J5: =VLOOKUP(financials[[#This Row],[productid]],Products!$B$2:$H$10,4) -> 10 | K5: =financials[[#This Row],[Net Sales]]-financials[[#This Row],[COGS]] -> 105.5 | L5: 44087 | M5: C0003
A6: Government | B6: Philipines | C6: 103 | D6: Medium | E6: 18 | F6: =VLOOKUP(financials[[#This Row],[productid]],Products!$B$2:$H$10,3) -> 28 | G6: =financials[[#This Row],[Units Sold]]*financials[[#This Row],[Sale Price]] -> 504 | H6: =IF(financials[[#This Row],[Discount Band]]="low",0.1,IF(financials[[#This Row],[Discount Band]]="medium",0.15,0.3)) -> 0.15 | I6: =financials[[#This Row],[Gross Sales]]-financials[[#This Row],[Gross Sales]]*financials[[#This Row],[Discounts]] -> 428.4 | J6: =VLOOKUP(financials[[#This Row],[productid]],Products!$B$2:$H$10,4) -> 15 | K6: =financials[[#This Row],[Net Sales]]-financials[[#This Row],[COGS]] -> 413.4 | L6: 44598 | M6: B0101
A7: Midmarket | B7: Philipines | C7: 101 | D7: Low | E7: 10 | F7: =VLOOKUP(financials[[#This Row],[productid]],Products!$B$2:$H$10,3) -> 23 | G7: =financials[[#This Row],[Units Sold]]*financials[[#This Row],[Sale Price]] -> 230 | H7: =IF(financials[[#This Row],[Discount Band]]="low",0.1,IF(financials[[#This Row],[Discount Band]]="medium",0.15,0.3)) -> 0.1 | I7: =financials[[#This Row],[Gross Sales]]-financials[[#This Row],[Gross Sales]]*financials[[#This Row],[Discounts]] -> 207 | J7: =VLOOKUP(financials[[#This Row],[productid]],Products!$B$2:$H$10,4) -> 9.95 | K7: =financials[[#This Row],[Net Sales]]-financials[[#This Row],[COGS]] -> 197.05 | L7: 44780 | M7: C0003
A8: Government | B8: Philipines | C8: 109 | D8: High | E8: 9 | F8: =VLOOKUP(financials[[#This Row],[productid]],Products!$B$2:$H$10,3) -> 36 | G8: =financials[[#This Row],[Units Sold]]*financials[[#This Row],[Sale Price]] -> 324 | H8: =IF(financials[[#This Row],[Discount Band]]="low",0.1,IF(financials[[#This Row],[Discount Band]]="medium",0.15,0.3)) -> 0.3 | I8: =financials[[#This Row],[Gross Sales]]-financials[[#This Row],[Gross Sales]]*financials[[#This Row],[Discounts]] -> 226.8 | J8: =VLOOKUP(financials[[#This Row],[productid]],Products!$B$2:$H$10,4) -> 16.8 | K8: =financials[[#This Row],[Net Sales]]-financials[[#This Row],[COGS]] -> 210 | L8: 45189 | M8: B0001
A9: Channel Partners | B9: Philipines | C9: 109 | D9: High | E9: 5 | F9: =VLOOKUP(financials[[#This Row],[productid]],Products!$B$2:$H$10,3) -> 36 | G9: =financials[[#This Row],[Units Sold]]*financials[[#This Row],[Sale Price]] -> 180 | H9: =IF(financials[[#This Row],[Discount Band]]="low",0.1,IF(financials[[#This Row],[Discount Band]]="medium",0.15,0.3)) -> 0.3 | I9: =financials[[#This Row],[Gross Sales]]-financials[[#This Row],[Gross Sales]]*financials[[#This Row],[Discounts]] -> 126 | J9: =VLOOKUP(financials[[#This Row],[productid]],Products!$B$2:$H$10,4) -> 16.8 | K9: =financials[[#This Row],[Net Sales]]-financials[[#This Row],[COGS]] -> 109.2 | L9: 44265 | M9: B0101
A10: Government | B10: Philipines | C10: 108 | D10: Medium | E10: 18 | F10: =VLOOKUP(financials[[#This Row],[productid]],Products!$B$2:$H$10,3) -> 5.5 | G10: =financials[[#This Row],[Units Sold]]*financials[[#This Row],[Sale Price]] -> 99 | H10: =IF(financials[[#This Row],[Discount Band]]="low",0.1,IF(financials[[#This Row],[Discount Band]]="medium",0.15,0.3)) -> 0.15 | I10: =financials[[#This Row],[Gross Sales]]-financials[[#This Row],[Gross Sales]]*financials[[#This Row],[Discounts]] -> 84.15 | J10: =VLOOKUP(financials[[#This Row],[productid]],Products!$B$2:$H$10,4) -> 3.99 | K10: =financials[[#This Row],[Net Sales]]-financials[[#This Row],[COGS]] -> 80.16 | L10: 44585 | M10: C0002
A11: Government | B11: Philipines | C11: 102 | D11: High | E11: 13 | F11: =VLOOKUP(financials[[#This Row],[productid]],Products!$B$2:$H$10,3) -> 15 | G11: =financials[[#This Row],[Units Sold]]*financials[[#This Row],[Sale Price]] -> 195 | H11: =IF(financials[[#This Row],[Discount Band]]="low",0.1,IF(financials[[#This Row],[Discount Band]]="medium",0.15,0.3)) -> 0.3 | I11: =financials[[#This Row],[Gross Sales]]-financials[[#This Row],[Gross Sales]]*financials[[#This Row],[Discounts]] -> 136.5 | J11: =VLOOKUP(financials[[#This Row],[productid]],Products!$B$2:$H$10,4) -> 13.95 | K11: =financials[[#This Row],[Net Sales]]-financials[[#This Row],[COGS]] -> 122.55 | L11: 44891 | M11: C0002
A12: Midmarket | B12: Philipines | C12: 104 | D12: High | E12: 11 | F12: =VLOOKUP(financials[[#This Row],[productid]],Products!$B$2:$H$10,3) -> 5.9 | G12: =financials[[#This Row],[Units Sold]]*financials[[#This Row],[Sale Price]] -> 64.9 | H12: =IF(financials[[#This Row],[Discount Band]]="low",0.1,IF(financials[[#This Row],[Discount Band]]="medium",0.15,0.3)) -> 0.3 | I12: =financials[[#This Row],[Gross Sales]]-financials[[#This Row],[Gross Sales]]*financials[[#This Row],[Discounts]] -> 45.43 | J12: =VLOOKUP(financials[[#This Row],[productid]],Products!$B$2:$H$10,4) -> 2.9 | K12: =financials[[#This Row],[Net Sales]]-financials[[#This Row],[COGS]] -> 42.53 | L12: 45232 | M12: C0003
A13: Government | B13: Philipines | C13: 105 | D13: High | E13: 11 | F13: =VLOOKUP(financials[[#This Row],[productid]],Products!$B$2:$H$10,3) -> 15 | G13: =financials[[#This Row],[Units Sold]]*financials[[#This Row],[Sale Price]] -> 165 | H13: =IF(financials[[#This Row],[Discount Band]]="low",0.1,IF(financials[[#This Row],[Discount Band]]="medium",0.15,0.3)) -> 0.3 | I13: =financials[[#This Row],[Gross Sales]]-financials[[#This Row],[Gross Sales]]*financials[[#This Row],[Discounts]] -> 115.5 | J13: =VLOOKUP(financials[[#This Row],[productid]],Products!$B$2:$H$10,4) -> 10 | K13: =financials[[#This Row],[Net Sales]]-financials[[#This Row],[COGS]] -> 105.5 | L13: 44040 | M13: C0003
... A4901: Enterprise | B4901: Malaysia | C4901: 106 | D4901: High | E4901: 20 | F4901: =VLOOKUP(financials[[#This Row],[productid]],Products!$B$2:$H$10,3) -> 25 | G4901: =financials[[#This Row],[Units Sold]]*financials[[#This Row],[Sale Price]] -> 500 | H4901: =IF(financials[[#This Row],[Discount Band]]="low",0.1,IF(financials[[#This Row],[Discount Band]]="medium",0.15,0.3)) -> 0.3 | I4901: =financials[[#This Row],[Gross Sales]]-financials[[#This Row],[Gross Sales]]*financials[[#This Row],[Discounts]] -> 350 | J4901: =VLOOKUP(financials[[#This Row],[productid]],Products!$B$2:$H$10,4) -> 9.1 | K4901: =financials[[#This Row],[Net Sales]]-financials[[#This Row],[COGS]] -> 340.9 | L4901: 44535 | M4901: B0001

Sheet SalesByRegion
A1: orderid | B1: Sales Date | C1: region | D1: empid | E1: prodid | F1: ShipperID | G1: Qty | H1: SalesAmt
A2: 1 | B2: 44047 | C2: east | D2: A0001 | E2: 103 | F2: 11 | G2: 25 | H2: 17300
A3: 1 | B3: 45655 | C3: west | D3: A0001 | E3: 106 | F3: 14 | G3: 42 | H3: 14143
A4: 1 | B4: 44015 | C4: east | D4: B0001 | E4: 103 | F4: 11 | G4: 45 | H4: 31343
A5: 1 | B5: 45302 | C5: west | D5: B0001 | E5: 105 | F5: 11 | G5: 45 | H5: 31626
A6: 1 | B6: 44472 | C6: north | D6: B0001 | E6: 105 | F6: 15 | G6: 78 | H6: 42477
A7: 1 | B7: 44329 | C7: south | D7: B0001 | E7: 103 | F7: 13 | G7: 43 | H7: 32407
A8: 1 | B8: 45559 | C8: east | D8: B0001 | E8: 104 | F8: 12 | G8: 50 | H8: 45079
A9: 1 | B9: 44791 | C9: west | D9: B0101 | E9: 104 | F9: 15 | G9: 86 | H9: 44515
A10: 1 | B10: 45525 | C10: north | D10: B0101 | E10: 102 | F10: 14 | G10: 88 | H10: 48090
A11: 1 | B11: 45456 | C11: east | D11: B0101 | E11: 109 | F11: 15 | G11: 92 | H11: 30206
A12: 1 | B12: 43922 | C12: west | D12: C0002 | E12: 105 | F12: 15 | G12: 91 | H12: 33245
A13: 1 | B13: 45396 | C13: south | D13: C0003 | E13: 104 | F13: 14 | G13: 85 | H13: 39026
... A2197: 70 | B2197: 44411 | C2197: south | D2197: E0013 | E2197: 107 | F2197: 11 | G2197: 73 | H2197: 15068
A2198: 69 | B2198: 45870 | C2198: east | D2198: F0001 | E2198: 105 | F2198: 11 | G2198: 85 | H2198: =G2198*G2198 -> 7225
A2199: 68 | B2199: 45870 | C2199: south | D2199: F0001 | E2199: 102 | F2199: 11 | G2199: 78 | H2199: 4520

Sheet Shippers
A1: no | B1: shipperid | C1: shipname | D1: freight | E1: min fees | F1: max fees | G1: min kg | H1: max kg
A2: 1 | B2: 11 | C2: Sima Tech | D2: 32.38 | E2: =+G2*15 -> 15000 | F2: =H2*20 -> 200000 | G2: 1000 | H2: 10000
A3: 2 | B3: 12 | C3: Trans West | D3: 11.61 | E3: =+G3*15 -> 18000 | F3: =H3*20 -> 70000 | G3: 1200 | H3: 3500
A4: 3 | B4: 13 | C4: Maersk | D4: 65.83 | E4: =+G4*15 -> 82500 | F4: =H4*20 -> 1200000 | G4: 5500 | H4: 60000
A5: 4 | B5: 14 | C5: Kontena National | D5: 41.34 | E5: =+G5*15 -> 52500 | F5: =H5*20 -> 780000 | G5: 3500 | H5: 39000
A6: 5 | B6: 15 | C6: MTT Shipping | D6: 51.38 | E6: =+G6*15 -> 67500 | F6: =H6*20 -> 1140000 | G6: 4500 | H6: 57000

Sheet Suppliers
A1: no | B1: suppid | C1: company | D1: name | E1: phone
A2: 1 | B2: 86563 | C2: Supplier Co A | D2: Mike Firt | E2: 7163615121
A3: 2 | B3: 96352 | C3: Co B | D3: Josie Lind | E3: 1831635671
A4: 3 | B4: 48256 | C4: East Asia Supplier | D4: Joanna Threven | E4: 2936827338

Sheet RandomNList
B2: For Sheet: | C2: Column | D2: Start | E2: End | F2: Formula | H2: no | I2: continent | K2: no | L2: regionname | N2: no | O2: salesbycountry | P2: Unit Sold-min | Q2: Unit Sold-max | S2: no | T2: Segment | V2: no | W2: empid | X2: name | Z2: no | AA2: Discounts | AC2: Date-start | AD2: Date-end
B3: SalesByRegion | C3: SalesAmount | D3: 2500 | E3: 25000 | F3: =RANDBETWEEN(D3,E3) -> 5289 | H3: 1 | I3: Africa | K3: 1 | L3: Northern Africa | N3: 1 | O3: Australia | P3: 140 | Q3: 300 | S3: 1 | T3: Government | V3: 1 | W3: A0001 | X3: Osawa | Z3: 1 | AA3: 0 | AC3: 43831 | AD3: 45657
B4: Any | C4: ID | D4: 1 | E4: 100 | F4: =RANDBETWEEN(D4,E4) -> 52 | H4: 2 | I4: Antarctica | K4: 2 | L4: Middle Africa | N4: 2 | O4: Brazil | P4: 140 | Q4: 300 | S4: 2 | T4: Channel Partners | V4: 2 | W4: B0001 | X4: Ruby Kaur | Z4: 2 | AA4: 0.1
B5: Any | C5: SalesPeriod | D5: 2020 | E5: 2022 | F5: =RANDBETWEEN(D5,E5) -> 2020 | H5: 3 | I5: Asia | K5: 3 | L5: Western Africa | N5: 3 | O5: Canada | P5: 140 | Q5: 300 | S5: 3 | T5: Enterprise | V5: 3 | W5: B0101 | X5: Krishna Deva | Z5: 3 | AA5: 0.25
B6: SalesByCountry | C6: Product | F6: =RANDBETWEEN(MIN(Products!$B$2:$B$10),MAX(Products!$B$2:$B$10)) -> 102 | H6: 4 | I6: Europe | K6: 4 | L6: Southern Africa | N6: 4 | O6: Chile | P6: 140 | Q6: 300 | S6: 4 | T6: Midmarket | V6: 4 | W6: C0002 | X6: Devi Sunes
B7: SalesByCountry | C7: country | F7: =VLOOKUP(RANDBETWEEN(1,37),rnlcountry,2) -> Philipines | H7: 5 | I7: North America | K7: 5 | L7: Eastern Africa | N7: 5 | O7: China | P7: 1000 | Q7: 4000 | S7: 5 | T7: Small Business | V7: 5 | W7: C0003 | X7: Jason Wong
B8: SalesByCountry | C8: Units Sold | F8: =RANDBETWEEN(VLOOKUP($C3,rnlunitsold,2),VLOOKUP($C3,rnlunitsold,3)) -> 226 | H8: 6 | I8: Oceania | K8: 6 | L8: Antarctica | N8: 6 | O8: Denmark | P8: 200 | Q8: 500 | V8: 6 | W8: C0005 | X8: Llian Vecteezy
B9: SalesByCountry | C9: Salesprice | D9: 1 | E9: 2 | H9: 7 | I9: South America | K9: 7 | L9: Southern Asia | N9: 7 | O9: China | P9: 1000 | Q9: 4000 | V9: 7 | W9: C0011 | X9: Brian Ng
B10: SalesByCountry | C10: salesperson | F10: =VLOOKUP(RANDBETWEEN(1,11),rnlsalesperson,3) -> Sofia Kowalskki | K10: 8 | L10: Western Asia | N10: 8 | O10: China | P10: 1000 | Q10: 4000 | V10: 8 | W10: C0020 | X10: Abu Bakar
B11: OrderDetails | C11: supplierid | D11: 1 | E11: 3 | F11: =VLOOKUP(RANDBETWEEN(1,3),Suppliers!$A$2:$B$4,2) -> 86563 | H11: no | I11: supplierid | K11: 9 | L11: South-eastern Asia | N11: 9 | O11: France | P11: 200 | Q11: 500 | V11: 9 | W11: E0001 | X11: Pater Aria
B12: OrderDetails | C12: OrderID | F12: =RANDBETWEEN(30,79) -> 77 | H12: 1 | I12: 48256 | K12: 10 | L12: Eastern Asia | N12: 10 | O12: Germany | P12: 200 | Q12: 500 | V12: 10 | W12: E0012 | X12: Jamal Ahmad
B13: OrderDetails | C13: ShipperID | F13: =RANDBETWEEN(MIN(Shippers!$B$2:$B$9),MAX(Shippers!$B$2:$B$9)) -> 13 | H13: 2 | I13: 86563 | K13: 11 | L13: Central Asia | N13: 11 | O13: India | P13: 150 | Q13: 350 | V13: 11 | W13: E0013 | X13: Sofia Kowalskki
B14: OrderDetails | C14: custid | D14: =MIN(Customers!A2:A9) -> 1 | E14: =MAX(Customers!A2:A9) -> 8 | F14: =RANDBETWEEN(MIN(Customers!$A$2:$A$9),MAX(Customers!$A$2:$A$9)) -> 5 | H14: 3 | I14: 96352 | K14: 12 | L14: Northern Europe | N14: 12 | O14: Indonesia | P14: 300 | Q14: 600
B15: OrderDetails | C15: EmpID | F15: =VLOOKUP(RANDBETWEEN(1,11),rnlsalesperson,2) -> E0013 | K15: 13 | L15: Southern Europe | N15: 13 | O15: China | P15: 1000 | Q15: 4000
B16: OrderDetails | C16: ProdID | D16: =MIN(Products!B2:B10) -> 101 | E16: =MAX(Products!B2:B10) -> 109 | F16: =RANDBETWEEN(MIN(Products!$B$2:$B$9),MAX(Products!$B$2:$B$9)) -> 102 | K16: 14 | L16: Western Europe | N16: 14 | O16: Japan | P16: 250 | Q16: 700
B17: OrderDetails | C17: Qty | D17: 5 | E17: 250 | F17: =RANDBETWEEN(D17,E17) -> 220 | K17: 15 | L17: Eastern Europe | N17: 15 | O17: Malaysia | P17: 500 | Q17: 700
B18: OrderDetails | C18: Discount | F18: =VLOOKUP(RANDBETWEEN(1,3),RandomNList!$Z$3:$AA$5,2) -> 0.25 | K18: 16 | L18: Caribbean | N18: 16 | O18: Mexico | P18: 100 | Q18: 300
B19: OrderDetails | C19: AdminFees | F19: =RANDBETWEEN(10,59) -> 49 | K19: 17 | L19: Central America | N19: 17 | O19: Mongolia | P19: 200 | Q19: 300
K20: 18 | L20: Northern America | N20: 18 | O20: Malaysia | P20: 500 | Q20: 1000
K21: 19 | L21: Polynesia | N21: 19 | O21: Malaysia | P21: 300 | Q21: 1500
K22: 20 | L22: Australia and New Zealand | N22: 20 | O22: Malaysia | P22: 1000 | Q22: 2000
K23: 21 | L23: Melanesia | N23: 21 | O23: Malaysia | P23: 1500 | Q23: 5000
K24: 22 | L24: Micronesia | N24: 22 | O24: Norway | P24: 150 | Q24: 250
K25: 23 | L25: South America | N25: 23 | O25: Philipines | P25: 10 | Q25: 110
N26: 24 | O26: Republic of Korea | P26: 25 | Q26: 440
N27: 25 | O27: South Africa | P27: 50 | Q27: 200
N28: 26 | O28: United States of America | P28: 1000 | Q28: 2000
N29: 27 | O29: Spain | P29: 200 | Q29: 500
N30: 28 | O30: United States of America | P30: 1000 | Q30: 2000
N31: 29 | O31: Sweden | P31: 250 | Q31: 550
N32: 30 | O32: Switzerland | P32: 140 | Q32: 300
N33: 31 | O33: Thailand | P33: 300 | Q33: 600
N34: 32 | O34: United States of America | P34: 1000 | Q34: 2000
N35: 33 | O35: Turkeye | P35: 140 | Q35: 300
N36: 34 | O36: United States of America | P36: 1000 | Q36: 2000
